<?xml version="1.0"?>
<robot xmlns:xacro="http://www.ros.org/wiki/xacro" name="robot">

  <!-- Robot Footprint -->
  <link name="base_footprint"/>

  <!-- base link -->
  <link name="base_link">
    <visual>
      <origin xyz="0 0 0.0" rpy="0 0 0"/>
      <geometry>
        <cylinder length="0.12" radius="0.10"/>
      </geometry>
      <material name="blue">
        <color rgba="0.1 0.1 1.0 0.5" /> 
      </material>
    </visual>
    <collision>
      <origin xyz="0 0 0.0" rpy="0 0 0"/>
      <geometry>
        <cylinder length="0.12" radius="0.10"/>
      </geometry>
      <material name="blue">
        <color rgba="0.1 0.1 1.0 0.5" /> 
      </material>
    </collision>
    <inertial>
      <mass value="0.2"/>
      <inertia ixx="0.0122666" ixy="0" ixz="0" iyy="0.0122666" iyz="0" izz="0.02"/>
    </inertial>
  </link>

  <!-- laser link -->
  <link name="laser_link">
    <visual>
      <origin xyz="0 0 0" rpy="0 0 0"/>
      <geometry>
        <cylinder length="0.02" radius="0.02"/>
      </geometry>
      <material name="black">
        <color rgba="0.0 0.0 0.0 0.5" /> 
      </material>
    </visual>
    <collision>
      <origin xyz="0 0 0" rpy="0 0 0"/>
      <geometry>
        <cylinder length="0.02" radius="0.02"/>
      </geometry>
      <material name="black">
        <color rgba="0.0 0.0 0.0 0.5" /> 
      </material>
    </collision>
    <inertial>
      <mass value="0.1"/>
      <inertia ixx="0.000190416666667" ixy="0" ixz="0" iyy="0.0001904" iyz="0" izz="0.00036"/>
    </inertial>
  </link>

  <link name="imu_link">
    <visual>
      <origin xyz="0 0 0.0" rpy="0 0 0"/>
      <geometry>
        <box size="0.02 0.02 0.02"/>
      </geometry>
    </visual>
    <collision>
      <origin xyz="0 0 0.0" rpy="0 0 0"/>
      <geometry>
        <box size="0.02 0.02 0.02"/>
      </geometry>
    </collision>
    <inertial>
      <mass value="0.1"/>
      <inertia ixx="0.000190416666667" ixy="0" ixz="0" iyy="0.0001904" iyz="0" izz="0.00036"/>
    </inertial>
  </link>

  <link name="left_wheel_link">
      <visual>
        <origin xyz="0 0 0" rpy="1.57079 0 0"/>
        <geometry>
          <cylinder length="0.04" radius="0.032"/>
        </geometry>
        <material name="black">
          <color rgba="0.0 0.0 0.0 0.5" /> 
        </material>
      </visual>
      <collision>
        <origin xyz="0 0 0" rpy="1.57079 0 0"/>
        <geometry>
          <cylinder length="0.04" radius="0.032"/>
        </geometry>
        <material name="black">
          <color rgba="0.0 0.0 0.0 0.5" /> 
        </material>
      </collision>
      <inertial>
        <mass value="0.2"/>
        <inertia ixx="0.000190416666667" ixy="0" ixz="0" iyy="0.0001904" iyz="0" izz="0.00036"/>
      </inertial>
  </link>
    
  <link name="right_wheel_link">
      <visual>
        <origin xyz="0 0 0" rpy="1.57079 0 0"/>
        <geometry>
          <cylinder length="0.04" radius="0.032"/>
        </geometry>
        <material name="black">
          <color rgba="0.0 0.0 0.0 0.5" /> 
        </material>
      </visual>
      <collision>
        <origin xyz="0 0 0" rpy="1.57079 0 0"/>
        <geometry>
          <cylinder length="0.04" radius="0.032"/>
        </geometry>
        <material name="black">
          <color rgba="0.0 0.0 0.0 0.5" /> 
        </material>
      </collision>
      <inertial>
        <mass value="0.2"/>
        <inertia ixx="0.000190416666667" ixy="0" ixz="0" iyy="0.0001904" iyz="0" izz="0.00036"/>
      </inertial>
  </link>
  
  <!-- base_joint -->
  <joint name="base_joint" type="fixed">
    <parent link="base_footprint"/>
    <child link="base_link"/>
    <origin xyz="0.0 0.0 0.076" rpy="0 0 0"/>
  </joint>

  <!-- laser joint -->
  <joint name="laser_joint" type="fixed">
      <parent link="base_link" />
      <child link="laser_link" />
      <origin xyz="0 0 0.075" />
  </joint>
  <!-- imu joint -->
  <joint name="imu_joint" type="fixed">
      <parent link="base_link" />
      <child link="imu_link" />
      <origin xyz="0 0 0.02" />
  </joint>

  <joint name="left_wheel_joint" type="continuous">
      <parent link="base_link" />
      <child link="left_wheel_link" />
      <origin xyz="-0.02 0.10 -0.06" />
      <axis xyz="0 1 0" />
      <limit effort="20" velocity="10"/>  <!-- 添加努力限制，支持扭矩 -->
      <dynamics damping="0.0" friction="0.0"/>
  </joint>

  <joint name="right_wheel_joint" type="continuous">
      <parent link="base_link" />
      <child link="right_wheel_link" />
      <origin xyz="-0.02 -0.10 -0.06" />
      <axis xyz="0 1 0" />
      <limit effort="20" velocity="10"/>  <!-- 添加努力限制，支持扭矩 -->
      <dynamics damping="0.0" friction="0.0"/>
  </joint>

  <link name="caster_link">
      <visual>
        <origin xyz="0 0 0" rpy="1.57079 0 0"/>
        <geometry>
            <sphere radius="0.016"/>
        </geometry>
        <material name="black">
          <color rgba="0.0 0.0 0.0 0.5" /> 
        </material>
      </visual>
      <collision>
        <origin xyz="0 0 0" rpy="1.57079 0 0"/>
        <geometry>
            <sphere radius="0.016"/>
        </geometry>
        <material name="black">
          <color rgba="0.0 0.0 0.0 0.5" /> 
        </material>
      </collision>
      <inertial>
        <mass value="0.02"/>
        <inertia ixx="0.000190416666667" ixy="0" ixz="0" iyy="0.0001904" iyz="0" izz="0.00036"/>
      </inertial>
  </link>
    
  <joint name="caster_joint" type="fixed">
      <parent link="base_link" />
      <child link="caster_link" />
      <origin xyz="0.06 0.0 -0.076" />
      <axis xyz="0 1 0" />
  </joint>

  <!-- 材质和摩擦（保持原样） -->
  <gazebo reference="caster_link">
    <material>Gazebo/Black</material>
  </gazebo>

  <gazebo reference="caster_link">
    <mu1 value="0.0"/>
    <mu2 value="0.0"/>
    <kp value="1000000.0" />
    <kd value="10.0" />
  </gazebo>

  <gazebo reference="laser_link">
    <material>Gazebo/Black</material>
  </gazebo>

  <!-- IMU 传感器：内置类型，无 ROS 插件 -->
  <gazebo reference="imu_link">
    <sensor name="imu_sensor" type="imu">
      <always_on>true</always_on>
      <update_rate>100</update_rate>
      <visualize>true</visualize>
      <topic>/robot/imu</topic>  <!-- 输出话题 -->
      <imu>
        <angular_velocity>
          <x>
            <noise type="gaussian">
              <mean>0.0</mean>
              <stddev>2e-4</stddev>
              <bias_mean>0.0000075</bias_mean>
              <bias_stddev>0.0000008</bias_stddev>
            </noise>
          </x>
          <y>
            <noise type="gaussian">
              <mean>0.0</mean>
              <stddev>2e-4</stddev>
              <bias_mean>0.0000075</bias_mean>
              <bias_stddev>0.0000008</bias_stddev>
            </noise>
          </y>
          <z>
            <noise type="gaussian">
              <mean>0.0</mean>
              <stddev>2e-4</stddev>
              <bias_mean>0.0000075</bias_mean>
              <bias_stddev>0.0000008</bias_stddev>
            </noise>
          </z>
        </angular_velocity>
        <linear_acceleration>
          <x>
            <noise type="gaussian">
              <mean>0.0</mean>
              <stddev>1.7e-2</stddev>
              <bias_mean>0.1</bias_mean>
              <bias_stddev>0.001</bias_stddev>
            </noise>
          </x>
          <y>
            <noise type="gaussian">
              <mean>0.0</mean>
              <stddev>1.7e-2</stddev>
              <bias_mean>0.1</bias_mean>
              <bias_stddev>0.001</bias_stddev>
            </noise>
          </y>
          <z>
            <noise type="gaussian">
              <mean>0.0</mean>
              <stddev>1.7e-2</stddev>
              <bias_mean>0.1</bias_mean>
              <bias_stddev>0.001</bias_stddev>
            </noise>
          </z>
        </linear_acceleration>
      </imu>
    </sensor>
  </gazebo>

  <!-- LiDAR 传感器：使用 gpu_lidar 类型 -->
  <gazebo reference="laser_link">
    <sensor name="laser_sensor" type="gpu_lidar">
      <always_on>true</always_on>
      <visualize>true</visualize>
      <update_rate>5</update_rate>
      <topic>/scan</topic>  <!-- 输出话题 -->
      <lidar>  <!-- 替换原 <ray> -->
        <scan>
          <horizontal>
            <samples>360</samples>
            <resolution>1.000000</resolution>
            <min_angle>0.000000</min_angle>
            <max_angle>6.280000</max_angle>
          </horizontal>
        </scan>
        <range>
          <min>0.120000</min>
          <max>3.5</max>
          <resolution>0.015000</resolution>
        </range>
        <noise>
          <type>gaussian</type>
          <mean>0.0</mean>
          <stddev>0.01</stddev>
        </noise>
      </lidar>
    </sensor>
  </gazebo>

  <!-- 模型级插件：差速驱动和关节状态发布 -->
<gazebo>
  <!-- 1. 差速驱动插件（官方最新版） -->
  <plugin filename="gz-sim-diff-drive-system" name="gz::sim::systems::DiffDrive">
    <!-- ROS 2 桥接（可选，如果你用了 ros_gz_bridge） -->
    <ros>
      <namespace>/</namespace>          <!-- 建议改成 /robot1 之类避免多机器人冲突 -->
      <remapping>cmd_vel:=cmd_vel</remapping>
      <remapping>odom:=odom</remapping>
    </ros>

    <publish_joint_state>true</publish_joint_state>       
    <joint_state_topic>/joint_states</joint_state_topic>
    
    <!-- 左右轮关节名（必须和你 URDF 里完全一模一样！） -->
    <left_joint>left_wheel_joint</left_joint>
    <right_joint>right_wheel_joint</right_joint>

    <!-- 物理参数（必须和实际模型一致！） -->
    <wheel_separation>0.20</wheel_separation>      <!-- 两轮中心距离，单位：米 -->
    <wheel_diameter>0.064</wheel_diameter>         <!-- 轮子直径，单位：米 -->

    <!-- 限制（根据你的电机调整） -->
    <max_wheel_torque>20</max_wheel_torque>
    <max_wheel_acceleration>5.0</max_wheel_acceleration>
    <max_linear_acceleration>2.0</max_linear_acceleration>

    <!-- 发布设置（关键！） -->
    <publish_odom>true</publish_odom>
    <publish_odom_tf>true</publish_odom_tf>        <!-- 发布 odom → base_footprint 的 TF -->
    <publish_wheel_tf>true</publish_wheel_tf>     <!-- 一般设 false，轮子 TF 不需要 -->

    <!-- TF 帧名 -->
    <odometry_frame>odom</odometry_frame>
    <robot_base_frame>base_footprint</robot_base_frame>

    <!-- 发布频率 -->
    <odom_publisher_frequency>50</odom_publisher_frequency>
  </plugin>

  <!-- 2. 关节状态发布插件 -->
  <!-- <plugin filename="gz-sim-joint-state-publisher-system" 
          name="gz::sim::systems::JointStatePublisher">
    <topic>/joint_states</topic>
    <joint_name>left_wheel_joint</joint_name>
    <joint_name>right_wheel_joint</joint_name>
    <include_all_joints>true</include_all_joints>
  </plugin> -->
</gazebo>

</robot>